Workbook

Sheet Instrucciones
B2: Plantilla para importar rúbrica desde Excel / CSV
B4: Llena únicamente la hoja “Criterios”. Los encabezados ya están listos con los nombres exactos que espera el importador.
B6: 1 | C6: Los encabezados obligatorios son: Area, Criterio, Descripcion_Criterio, Peso_Criterio, Insatisfactorio, Necesitas_Mejorar, Bueno, Satisfactorio y Excelente.
B7: 2 | C7: En Area usa solamente uno de estos valores: Desarrollo o DEV, Habilidades Blandas o SOFT, Ingles o ENGLISH.
B8: 3 | C8: Peso_Criterio debe ser un número entre 0 y 100. La suma total debe dar 100.
B9: 4 | C9: Las columnas de niveles guardan el texto descriptivo de cada nivel. Los puntajes se asignan automáticamente así: 0, 25, 50, 75 y 100.
B10: 5 | C10: Puedes escribir un criterio por fila. La hoja trae una alerta visual si los pesos no suman 100.
B11: 6 | C11: A la derecha de la hoja Criterios verás un ejemplo visual, pero la tabla principal está en blanco para capturar datos reales.

Sheet Criterios
A1: Carga desde Excel (.xlsx / .csv)
A3: Total pesos | B3: =SUM(D8:D207) | C3: Estado | D3: =IF(COUNTA(B8:B207)=0,"Empieza a cargar criterios",IF(B3=100,"Listo para importar","⚠️ Los pesos deben sumar 100"))
A4: Encabezados exactos del importador. La tabla principal está vacía; el ejemplo está a la derecha.
A5: ➕ Agregar criterio Escribe en la siguiente fila vacía de la tabla | K5: Ejemplo
A7: Area | B7: Criterio | C7: Descripcion_Criterio | D7: Peso_Criterio | E7: Insatisfactorio | F7: Necesitas_Mejorar | G7: Bueno | H7: Satisfactorio | I7: Excelente | K7: Area | L7: Criterio | M7: Descripcion_Criterio | N7: Peso_Criterio | O7: Insatisfactorio | P7: Necesitas_Mejorar | Q7: Bueno | R7: Satisfactorio | S7: Excelente
K8: Desarrollo | L8: Backend API | M8: Calidad de los endpoints | N8: 25 | O8: No entrega nada | P8: Errores en rutas | Q8: Funciona básico | R8: Sigue estándares | S8: Documentación perfecta

Sheet _IMPORT
A1: rubric_name | B1: rubric_weight | C1: grade_name | D1: grade_description | E1: grade_score | F1: area | G1: source_row
A2: =IF(Criterios!B8="","",Criterios!B8) | B2: =IF(Criterios!B8="","",Criterios!D8/100) | C2: =IF(Criterios!B8="","",'Insatisfactorio') | D2: =IF(Criterios!B8="","",Criterios!E8) | E2: =IF(Criterios!B8="","",0) | F2: =IF(Criterios!B8="","",Criterios!A8) | G2: =IF(Criterios!B8="","",8)
A3: =IF(Criterios!B8="","",Criterios!B8) | B3: =IF(Criterios!B8="","",Criterios!D8/100) | C3: =IF(Criterios!B8="","",'Necesitas_Mejorar') | D3: =IF(Criterios!B8="","",Criterios!F8) | E3: =IF(Criterios!B8="","",25) | F3: =IF(Criterios!B8="","",Criterios!A8) | G3: =IF(Criterios!B8="","",8)
A4: =IF(Criterios!B8="","",Criterios!B8) | B4: =IF(Criterios!B8="","",Criterios!D8/100) | C4: =IF(Criterios!B8="","",'Bueno') | D4: =IF(Criterios!B8="","",Criterios!G8) | E4: =IF(Criterios!B8="","",50) | F4: =IF(Criterios!B8="","",Criterios!A8) | G4: =IF(Criterios!B8="","",8)
A5: =IF(Criterios!B8="","",Criterios!B8) | B5: =IF(Criterios!B8="","",Criterios!D8/100) | C5: =IF(Criterios!B8="","",'Satisfactorio') | D5: =IF(Criterios!B8="","",Criterios!H8) | E5: =IF(Criterios!B8="","",75) | F5: =IF(Criterios!B8="","",Criterios!A8) | G5: =IF(Criterios!B8="","",8)
A6: =IF(Criterios!B8="","",Criterios!B8) | B6: =IF(Criterios!B8="","",Criterios!D8/100) | C6: =IF(Criterios!B8="","",'Excelente') | D6: =IF(Criterios!B8="","",Criterios!I8) | E6: =IF(Criterios!B8="","",100) | F6: =IF(Criterios!B8="","",Criterios!A8) | G6: =IF(Criterios!B8="","",8)
A7: =IF(Criterios!B9="","",Criterios!B9) | B7: =IF(Criterios!B9="","",Criterios!D9/100) | C7: =IF(Criterios!B9="","",'Insatisfactorio') | D7: =IF(Criterios!B9="","",Criterios!E9) | E7: =IF(Criterios!B9="","",0) | F7: =IF(Criterios!B9="","",Criterios!A9) | G7: =IF(Criterios!B9="","",9)
A8: =IF(Criterios!B9="","",Criterios!B9) | B8: =IF(Criterios!B9="","",Criterios!D9/100) | C8: =IF(Criterios!B9="","",'Necesitas_Mejorar') | D8: =IF(Criterios!B9="","",Criterios!F9) | E8: =IF(Criterios!B9="","",25) | F8: =IF(Criterios!B9="","",Criterios!A9) | G8: =IF(Criterios!B9="","",9)
A9: =IF(Criterios!B9="","",Criterios!B9) | B9: =IF(Criterios!B9="","",Criterios!D9/100) | C9: =IF(Criterios!B9="","",'Bueno') | D9: =IF(Criterios!B9="","",Criterios!G9) | E9: =IF(Criterios!B9="","",50) | F9: =IF(Criterios!B9="","",Criterios!A9) | G9: =IF(Criterios!B9="","",9)
A10: =IF(Criterios!B9="","",Criterios!B9) | B10: =IF(Criterios!B9="","",Criterios!D9/100) | C10: =IF(Criterios!B9="","",'Satisfactorio') | D10: =IF(Criterios!B9="","",Criterios!H9) | E10: =IF(Criterios!B9="","",75) | F10: =IF(Criterios!B9="","",Criterios!A9) | G10: =IF(Criterios!B9="","",9)
A11: =IF(Criterios!B9="","",Criterios!B9) | B11: =IF(Criterios!B9="","",Criterios!D9/100) | C11: =IF(Criterios!B9="","",'Excelente') | D11: =IF(Criterios!B9="","",Criterios!I9) | E11: =IF(Criterios!B9="","",100) | F11: =IF(Criterios!B9="","",Criterios!A9) | G11: =IF(Criterios!B9="","",9)
A12: =IF(Criterios!B10="","",Criterios!B10) | B12: =IF(Criterios!B10="","",Criterios!D10/100) | C12: =IF(Criterios!B10="","",'Insatisfactorio') | D12: =IF(Criterios!B10="","",Criterios!E10) | E12: =IF(Criterios!B10="","",0) | F12: =IF(Criterios!B10="","",Criterios!A10) | G12: =IF(Criterios!B10="","",10)
A13: =IF(Criterios!B10="","",Criterios!B10) | B13: =IF(Criterios!B10="","",Criterios!D10/100) | C13: =IF(Criterios!B10="","",'Necesitas_Mejorar') | D13: =IF(Criterios!B10="","",Criterios!F10) | E13: =IF(Criterios!B10="","",25) | F13: =IF(Criterios!B10="","",Criterios!A10) | G13: =IF(Criterios!B10="","",10)
A14: =IF(Criterios!B10="","",Criterios!B10) | B14: =IF(Criterios!B10="","",Criterios!D10/100) | C14: =IF(Criterios!B10="","",'Bueno') | D14: =IF(Criterios!B10="","",Criterios!G10) | E14: =IF(Criterios!B10="","",50) | F14: =IF(Criterios!B10="","",Criterios!A10) | G14: =IF(Criterios!B10="","",10)
A15: =IF(Criterios!B10="","",Criterios!B10) | B15: =IF(Criterios!B10="","",Criterios!D10/100) | C15: =IF(Criterios!B10="","",'Satisfactorio') | D15: =IF(Criterios!B10="","",Criterios!H10) | E15: =IF(Criterios!B10="","",75) | F15: =IF(Criterios!B10="","",Criterios!A10) | G15: =IF(Criterios!B10="","",10)
A16: =IF(Criterios!B10="","",Criterios!B10) | B16: =IF(Criterios!B10="","",Criterios!D10/100) | C16: =IF(Criterios!B10="","",'Excelente') | D16: =IF(Criterios!B10="","",Criterios!I10) | E16: =IF(Criterios!B10="","",100) | F16: =IF(Criterios!B10="","",Criterios!A10) | G16: =IF(Criterios!B10="","",10)
A17: =IF(Criterios!B11="","",Criterios!B11) | B17: =IF(Criterios!B11="","",Criterios!D11/100) | C17: =IF(Criterios!B11="","",'Insatisfactorio') | D17: =IF(Criterios!B11="","",Criterios!E11) | E17: =IF(Criterios!B11="","",0) | F17: =IF(Criterios!B11="","",Criterios!A11) | G17: =IF(Criterios!B11="","",11)
A18: =IF(Criterios!B11="","",Criterios!B11) | B18: =IF(Criterios!B11="","",Criterios!D11/100) | C18: =IF(Criterios!B11="","",'Necesitas_Mejorar') | D18: =IF(Criterios!B11="","",Criterios!F11) | E18: =IF(Criterios!B11="","",25) | F18: =IF(Criterios!B11="","",Criterios!A11) | G18: =IF(Criterios!B11="","",11)
A19: =IF(Criterios!B11="","",Criterios!B11) | B19: =IF(Criterios!B11="","",Criterios!D11/100) | C19: =IF(Criterios!B11="","",'Bueno') | D19: =IF(Criterios!B11="","",Criterios!G11) | E19: =IF(Criterios!B11="","",50) | F19: =IF(Criterios!B11="","",Criterios!A11) | G19: =IF(Criterios!B11="","",11)
A20: =IF(Criterios!B11="","",Criterios!B11) | B20: =IF(Criterios!B11="","",Criterios!D11/100) | C20: =IF(Criterios!B11="","",'Satisfactorio') | D20: =IF(Criterios!B11="","",Criterios!H11) | E20: =IF(Criterios!B11="","",75) | F20: =IF(Criterios!B11="","",Criterios!A11) | G20: =IF(Criterios!B11="","",11)
A21: =IF(Criterios!B11="","",Criterios!B11) | B21: =IF(Criterios!B11="","",Criterios!D11/100) | C21: =IF(Criterios!B11="","",'Excelente') | D21: =IF(Criterios!B11="","",Criterios!I11) | E21: =IF(Criterios!B11="","",100) | F21: =IF(Criterios!B11="","",Criterios!A11) | G21: =IF(Criterios!B11="","",11)
A22: =IF(Criterios!B12="","",Criterios!B12) | B22: =IF(Criterios!B12="","",Criterios!D12/100) | C22: =IF(Criterios!B12="","",'Insatisfactorio') | D22: =IF(Criterios!B12="","",Criterios!E12) | E22: =IF(Criterios!B12="","",0) | F22: =IF(Criterios!B12="","",Criterios!A12) | G22: =IF(Criterios!B12="","",12)
A23: =IF(Criterios!B12="","",Criterios!B12) | B23: =IF(Criterios!B12="","",Criterios!D12/100) | C23: =IF(Criterios!B12="","",'Necesitas_Mejorar') | D23: =IF(Criterios!B12="","",Criterios!F12) | E23: =IF(Criterios!B12="","",25) | F23: =IF(Criterios!B12="","",Criterios!A12) | G23: =IF(Criterios!B12="","",12)
A24: =IF(Criterios!B12="","",Criterios!B12) | B24: =IF(Criterios!B12="","",Criterios!D12/100) | C24: =IF(Criterios!B12="","",'Bueno') | D24: =IF(Criterios!B12="","",Criterios!G12) | E24: =IF(Criterios!B12="","",50) | F24: =IF(Criterios!B12="","",Criterios!A12) | G24: =IF(Criterios!B12="","",12)
A25: =IF(Criterios!B12="","",Criterios!B12) | B25: =IF(Criterios!B12="","",Criterios!D12/100) | C25: =IF(Criterios!B12="","",'Satisfactorio') | D25: =IF(Criterios!B12="","",Criterios!H12) | E25: =IF(Criterios!B12="","",75) | F25: =IF(Criterios!B12="","",Criterios!A12) | G25: =IF(Criterios!B12="","",12)
A26: =IF(Criterios!B12="","",Criterios!B12) | B26: =IF(Criterios!B12="","",Criterios!D12/100) | C26: =IF(Criterios!B12="","",'Excelente') | D26: =IF(Criterios!B12="","",Criterios!I12) | E26: =IF(Criterios!B12="","",100) | F26: =IF(Criterios!B12="","",Criterios!A12) | G26: =IF(Criterios!B12="","",12)
A27: =IF(Criterios!B13="","",Criterios!B13) | B27: =IF(Criterios!B13="","",Criterios!D13/100) | C27: =IF(Criterios!B13="","",'Insatisfactorio') | D27: =IF(Criterios!B13="","",Criterios!E13) | E27: =IF(Criterios!B13="","",0) | F27: =IF(Criterios!B13="","",Criterios!A13) | G27: =IF(Criterios!B13="","",13)
A28: =IF(Criterios!B13="","",Criterios!B13) | B28: =IF(Criterios!B13="","",Criterios!D13/100) | C28: =IF(Criterios!B13="","",'Necesitas_Mejorar') | D28: =IF(Criterios!B13="","",Criterios!F13) | E28: =IF(Criterios!B13="","",25) | F28: =IF(Criterios!B13="","",Criterios!A13) | G28: =IF(Criterios!B13="","",13)
A29: =IF(Criterios!B13="","",Criterios!B13) | B29: =IF(Criterios!B13="","",Criterios!D13/100) | C29: =IF(Criterios!B13="","",'Bueno') | D29: =IF(Criterios!B13="","",Criterios!G13) | E29: =IF(Criterios!B13="","",50) | F29: =IF(Criterios!B13="","",Criterios!A13) | G29: =IF(Criterios!B13="","",13)
A30: =IF(Criterios!B13="","",Criterios!B13) | B30: =IF(Criterios!B13="","",Criterios!D13/100) | C30: =IF(Criterios!B13="","",'Satisfactorio') | D30: =IF(Criterios!B13="","",Criterios!H13) | E30: =IF(Criterios!B13="","",75) | F30: =IF(Criterios!B13="","",Criterios!A13) | G30: =IF(Criterios!B13="","",13)
A31: =IF(Criterios!B13="","",Criterios!B13) | B31: =IF(Criterios!B13="","",Criterios!D13/100) | C31: =IF(Criterios!B13="","",'Excelente') | D31: =IF(Criterios!B13="","",Criterios!I13) | E31: =IF(Criterios!B13="","",100) | F31: =IF(Criterios!B13="","",Criterios!A13) | G31: =IF(Criterios!B13="","",13)
A32: =IF(Criterios!B14="","",Criterios!B14) | B32: =IF(Criterios!B14="","",Criterios!D14/100) | C32: =IF(Criterios!B14="","",'Insatisfactorio') | D32: =IF(Criterios!B14="","",Criterios!E14) | E32: =IF(Criterios!B14="","",0) | F32: =IF(Criterios!B14="","",Criterios!A14) | G32: =IF(Criterios!B14="","",14)
A33: =IF(Criterios!B14="","",Criterios!B14) | B33: =IF(Criterios!B14="","",Criterios!D14/100) | C33: =IF(Criterios!B14="","",'Necesitas_Mejorar') | D33: =IF(Criterios!B14="","",Criterios!F14) | E33: =IF(Criterios!B14="","",25) | F33: =IF(Criterios!B14="","",Criterios!A14) | G33: =IF(Criterios!B14="","",14)
A34: =IF(Criterios!B14="","",Criterios!B14) | B34: =IF(Criterios!B14="","",Criterios!D14/100) | C34: =IF(Criterios!B14="","",'Bueno') | D34: =IF(Criterios!B14="","",Criterios!G14) | E34: =IF(Criterios!B14="","",50) | F34: =IF(Criterios!B14="","",Criterios!A14) | G34: =IF(Criterios!B14="","",14)
A35: =IF(Criterios!B14="","",Criterios!B14) | B35: =IF(Criterios!B14="","",Criterios!D14/100) | C35: =IF(Criterios!B14="","",'Satisfactorio') | D35: =IF(Criterios!B14="","",Criterios!H14) | E35: =IF(Criterios!B14="","",75) | F35: =IF(Criterios!B14="","",Criterios!A14) | G35: =IF(Criterios!B14="","",14)
A36: =IF(Criterios!B14="","",Criterios!B14) | B36: =IF(Criterios!B14="","",Criterios!D14/100) | C36: =IF(Criterios!B14="","",'Excelente') | D36: =IF(Criterios!B14="","",Criterios!I14) | E36: =IF(Criterios!B14="","",100) | F36: =IF(Criterios!B14="","",Criterios!A14) | G36: =IF(Criterios!B14="","",14)
A37: =IF(Criterios!B15="","",Criterios!B15) | B37: =IF(Criterios!B15="","",Criterios!D15/100) | C37: =IF(Criterios!B15="","",'Insatisfactorio') | D37: =IF(Criterios!B15="","",Criterios!E15) | E37: =IF(Criterios!B15="","",0) | F37: =IF(Criterios!B15="","",Criterios!A15) | G37: =IF(Criterios!B15="","",15)
A38: =IF(Criterios!B15="","",Criterios!B15) | B38: =IF(Criterios!B15="","",Criterios!D15/100) | C38: =IF(Criterios!B15="","",'Necesitas_Mejorar') | D38: =IF(Criterios!B15="","",Criterios!F15) | E38: =IF(Criterios!B15="","",25) | F38: =IF(Criterios!B15="","",Criterios!A15) | G38: =IF(Criterios!B15="","",15)
A39: =IF(Criterios!B15="","",Criterios!B15) | B39: =IF(Criterios!B15="","",Criterios!D15/100) | C39: =IF(Criterios!B15="","",'Bueno') | D39: =IF(Criterios!B15="","",Criterios!G15) | E39: =IF(Criterios!B15="","",50) | F39: =IF(Criterios!B15="","",Criterios!A15) | G39: =IF(Criterios!B15="","",15)
A40: =IF(Criterios!B15="","",Criterios!B15) | B40: =IF(Criterios!B15="","",Criterios!D15/100) | C40: =IF(Criterios!B15="","",'Satisfactorio') | D40: =IF(Criterios!B15="","",Criterios!H15) | E40: =IF(Criterios!B15="","",75) | F40: =IF(Criterios!B15="","",Criterios!A15) | G40: =IF(Criterios!B15="","",15)
...
